{
 "cells": [
  {
   "cell_type": "code",
   "execution_count": 1,
   "metadata": {},
   "outputs": [],
   "source": [
    "import os\n",
    "import tensorflow as tf\n",
    "from tensorflow.keras.models import load_model\n",
    "from tensorflow.keras.preprocessing.image import ImageDataGenerator\n",
    "from Steganalysis.config.configuration import ConfigurationManager"
   ]
  },
  {
   "cell_type": "code",
   "execution_count": 2,
   "metadata": {},
   "outputs": [
    {
     "name": "stdout",
     "output_type": "stream",
     "text": [
      "[2024-11-09 17:26:36,897: INFO: common: yaml file: E:\\Projects\\Steganalysis\\config\\config.yaml loaded successfully]\n",
      "[2024-11-09 17:26:36,910: INFO: common: yaml file: E:\\Projects\\Steganalysis\\params.yaml loaded successfully]\n",
      "[2024-11-09 17:26:36,910: INFO: common: created directory at: artifacts]\n",
      "[2024-11-09 17:26:36,918: INFO: common: created directory at: artifacts/training]\n"
     ]
    }
   ],
   "source": [
    "config_manager = ConfigurationManager()\n",
    "model_training_config = config_manager.get_model_training_config()"
   ]
  },
  {
   "cell_type": "code",
   "execution_count": 4,
   "metadata": {},
   "outputs": [
    {
     "ename": "ValueError",
     "evalue": "File not found: filepath=artifacts\\prepare_base_model\\base_model_updated.keras. Please ensure the file is an accessible `.keras` zip file.",
     "output_type": "error",
     "traceback": [
      "\u001b[1;31m---------------------------------------------------------------------------\u001b[0m",
      "\u001b[1;31mValueError\u001b[0m                                Traceback (most recent call last)",
      "Cell \u001b[1;32mIn[4], line 1\u001b[0m\n\u001b[1;32m----> 1\u001b[0m model \u001b[38;5;241m=\u001b[39m \u001b[43mload_model\u001b[49m\u001b[43m(\u001b[49m\u001b[43mmodel_training_config\u001b[49m\u001b[38;5;241;43m.\u001b[39;49m\u001b[43mmodel_path\u001b[49m\u001b[43m)\u001b[49m\n\u001b[0;32m      2\u001b[0m model\u001b[38;5;241m.\u001b[39msummary()\n",
      "File \u001b[1;32me:\\System_Files\\Anaconda\\envs\\my_envi_steganalysis\\lib\\site-packages\\keras\\src\\saving\\saving_api.py:200\u001b[0m, in \u001b[0;36mload_model\u001b[1;34m(filepath, custom_objects, compile, safe_mode)\u001b[0m\n\u001b[0;32m    196\u001b[0m     \u001b[38;5;28;01mreturn\u001b[39;00m legacy_h5_format\u001b[38;5;241m.\u001b[39mload_model_from_hdf5(\n\u001b[0;32m    197\u001b[0m         filepath, custom_objects\u001b[38;5;241m=\u001b[39mcustom_objects, \u001b[38;5;28mcompile\u001b[39m\u001b[38;5;241m=\u001b[39m\u001b[38;5;28mcompile\u001b[39m\n\u001b[0;32m    198\u001b[0m     )\n\u001b[0;32m    199\u001b[0m \u001b[38;5;28;01melif\u001b[39;00m \u001b[38;5;28mstr\u001b[39m(filepath)\u001b[38;5;241m.\u001b[39mendswith(\u001b[38;5;124m\"\u001b[39m\u001b[38;5;124m.keras\u001b[39m\u001b[38;5;124m\"\u001b[39m):\n\u001b[1;32m--> 200\u001b[0m     \u001b[38;5;28;01mraise\u001b[39;00m \u001b[38;5;167;01mValueError\u001b[39;00m(\n\u001b[0;32m    201\u001b[0m         \u001b[38;5;124mf\u001b[39m\u001b[38;5;124m\"\u001b[39m\u001b[38;5;124mFile not found: filepath=\u001b[39m\u001b[38;5;132;01m{\u001b[39;00mfilepath\u001b[38;5;132;01m}\u001b[39;00m\u001b[38;5;124m. \u001b[39m\u001b[38;5;124m\"\u001b[39m\n\u001b[0;32m    202\u001b[0m         \u001b[38;5;124m\"\u001b[39m\u001b[38;5;124mPlease ensure the file is an accessible `.keras` \u001b[39m\u001b[38;5;124m\"\u001b[39m\n\u001b[0;32m    203\u001b[0m         \u001b[38;5;124m\"\u001b[39m\u001b[38;5;124mzip file.\u001b[39m\u001b[38;5;124m\"\u001b[39m\n\u001b[0;32m    204\u001b[0m     )\n\u001b[0;32m    205\u001b[0m \u001b[38;5;28;01melse\u001b[39;00m:\n\u001b[0;32m    206\u001b[0m     \u001b[38;5;28;01mraise\u001b[39;00m \u001b[38;5;167;01mValueError\u001b[39;00m(\n\u001b[0;32m    207\u001b[0m         \u001b[38;5;124mf\u001b[39m\u001b[38;5;124m\"\u001b[39m\u001b[38;5;124mFile format not supported: filepath=\u001b[39m\u001b[38;5;132;01m{\u001b[39;00mfilepath\u001b[38;5;132;01m}\u001b[39;00m\u001b[38;5;124m. \u001b[39m\u001b[38;5;124m\"\u001b[39m\n\u001b[0;32m    208\u001b[0m         \u001b[38;5;124m\"\u001b[39m\u001b[38;5;124mKeras 3 only supports V3 `.keras` files and \u001b[39m\u001b[38;5;124m\"\u001b[39m\n\u001b[1;32m   (...)\u001b[0m\n\u001b[0;32m    217\u001b[0m         \u001b[38;5;124m\"\u001b[39m\u001b[38;5;124mmight have a different name).\u001b[39m\u001b[38;5;124m\"\u001b[39m\n\u001b[0;32m    218\u001b[0m     )\n",
      "\u001b[1;31mValueError\u001b[0m: File not found: filepath=artifacts\\prepare_base_model\\base_model_updated.keras. Please ensure the file is an accessible `.keras` zip file."
     ]
    }
   ],
   "source": [
    "model = load_model(model_training_config.model_path)\n",
    "model.summary()"
   ]
  },
  {
   "cell_type": "code",
   "execution_count": null,
   "metadata": {},
   "outputs": [],
   "source": [
    "data_gen = ImageDataGenerator(rescale=1.0/255.0, validation_split=0.2)"
   ]
  },
  {
   "cell_type": "code",
   "execution_count": null,
   "metadata": {},
   "outputs": [],
   "source": [
    "data_dir = \"artifacts/data_ingestion/unzip_dir\" \n",
    "\n",
    "train_generator = data_gen.flow_from_directory(\n",
    "    directory=data_dir,\n",
    "    target_size=model_training_config.params_image_size[:2],\n",
    "    batch_size=model_training_config.batch_size,\n",
    "    class_mode=\"binary\",\n",
    "    subset=\"training\"\n",
    ")\n",
    "\n",
    "val_generator = data_gen.flow_from_directory(\n",
    "    directory=data_dir,\n",
    "    target_size=model_training_config.params_image_size[:2],\n",
    "    batch_size=model_training_config.batch_size,\n",
    "    class_mode=\"binary\",\n",
    "    subset=\"validation\"\n",
    ")\n",
    "\n",
    "\n",
    "callbacks = [\n",
    "    tf.keras.callbacks.TensorBoard(log_dir=os.path.join(model_training_config.callbacks_dir, \"tensorboard_log\")),\n",
    "    tf.keras.callbacks.ModelCheckpoint(filepath=model_training_config.model_path, save_best_only=True)\n",
    "]\n",
    "\n",
    "\n",
    "history = model.fit(\n",
    "    train_generator,\n",
    "    validation_data=val_generator,\n",
    "    epochs=model_training_config.epochs,\n",
    "    callbacks=callbacks\n",
    ")"
   ]
  },
  {
   "cell_type": "code",
   "execution_count": null,
   "metadata": {},
   "outputs": [],
   "source": [
    "\n",
    "# Step 7: Display Results (Optional)\n",
    "import matplotlib.pyplot as plt\n",
    "\n",
    "# Plot accuracy and loss curves\n",
    "plt.figure(figsize=(14, 5))\n",
    "\n",
    "# Plot training & validation accuracy values\n",
    "plt.subplot(1, 2, 1)\n",
    "plt.plot(history.history['accuracy'])\n",
    "plt.plot(history.history['val_accuracy'])\n",
    "plt.title('Model accuracy')\n",
    "plt.ylabel('Accuracy')\n",
    "plt.xlabel('Epoch')\n",
    "plt.legend(['Train', 'Validation'], loc='upper left')\n",
    "\n",
    "# Plot training & validation loss values\n",
    "plt.subplot(1, 2, 2)\n",
    "plt.plot(history.history['loss'])\n",
    "plt.plot(history.history['val_loss'])\n",
    "plt.title('Model loss')\n",
    "plt.ylabel('Loss')\n",
    "plt.xlabel('Epoch')\n",
    "plt.legend(['Train', 'Validation'], loc='upper left')\n",
    "\n",
    "plt.show()\n"
   ]
  }
 ],
 "metadata": {
  "kernelspec": {
   "display_name": "my_envi_steganalysis",
   "language": "python",
   "name": "python3"
  },
  "language_info": {
   "codemirror_mode": {
    "name": "ipython",
    "version": 3
   },
   "file_extension": ".py",
   "mimetype": "text/x-python",
   "name": "python",
   "nbconvert_exporter": "python",
   "pygments_lexer": "ipython3",
   "version": "3.10.15"
  }
 },
 "nbformat": 4,
 "nbformat_minor": 2
}
